usage: track_server.py [-h] [--path PATH] [--callback_urls CALLBACK_URLS]
                       [--port PORT] [--log_name LOG_NAME]
track_server.py: error: argument --port: invalid int value: ''
usage: track_server.py [-h] [--path PATH] [--callback_urls CALLBACK_URLS]
                       [--port PORT] [--log_name LOG_NAME]
track_server.py: error: argument --port: invalid int value: ''
10.5.24.119:50082 - - [28/May/2020 12:31:58] "HTTP/1.1 POST /track_label" - 200 OK
10.5.24.119:50214 - - [28/May/2020 12:33:02] "HTTP/1.1 POST /track_label" - 200 OK
10.5.24.119:50342 - - [28/May/2020 12:34:07] "HTTP/1.1 POST /track_label" - 200 OK
10.5.24.119:50476 - - [28/May/2020 12:35:12] "HTTP/1.1 POST /track_label" - 200 OK
10.5.24.119:50606 - - [28/May/2020 12:36:17] "HTTP/1.1 POST /track_label" - 200 OK
10.5.24.119:50736 - - [28/May/2020 12:37:22] "HTTP/1.1 POST /track_label" - 200 OK
10.5.24.119:50872 - - [28/May/2020 12:38:27] "HTTP/1.1 POST /track_label" - 200 OK
10.5.24.119:50998 - - [28/May/2020 12:39:32] "HTTP/1.1 POST /track_label" - 200 OK
10.5.24.119:51128 - - [28/May/2020 12:40:37] "HTTP/1.1 POST /track_label" - 200 OK
10.5.24.119:51260 - - [28/May/2020 12:41:42] "HTTP/1.1 POST /track_label" - 200 OK
10.5.24.119:51538 - - [28/May/2020 12:55:52] "HTTP/1.1 POST /track_label" - 200 OK
10.5.24.119:51722 - - [28/May/2020 12:57:22] "HTTP/1.1 POST /track_label" - 200 OK
10.5.24.119:51856 - - [28/May/2020 12:58:27] "HTTP/1.1 POST /track_label" - 200 OK
10.5.24.119:51986 - - [28/May/2020 12:59:32] "HTTP/1.1 POST /track_label" - 200 OK
10.5.24.119:52116 - - [28/May/2020 13:00:37] "HTTP/1.1 POST /track_label" - 200 OK
10.5.24.119:52250 - - [28/May/2020 13:01:42] "HTTP/1.1 POST /track_label" - 200 OK
10.5.24.119:52384 - - [28/May/2020 13:02:47] "HTTP/1.1 POST /track_label" - 200 OK
10.5.24.119:52516 - - [28/May/2020 13:03:52] "HTTP/1.1 POST /track_label" - 200 OK
10.5.24.119:52646 - - [28/May/2020 13:04:57] "HTTP/1.1 POST /track_label" - 200 OK
10.5.24.119:52778 - - [28/May/2020 13:06:02] "HTTP/1.1 POST /track_label" - 200 OK
10.5.24.119:52908 - - [28/May/2020 13:07:07] "HTTP/1.1 POST /track_label" - 200 OK
10.5.24.119:53040 - - [28/May/2020 13:08:12] "HTTP/1.1 POST /track_label" - 200 OK
10.5.24.119:53168 - - [28/May/2020 13:09:17] "HTTP/1.1 POST /track_label" - 200 OK
10.5.24.119:53298 - - [28/May/2020 13:10:22] "HTTP/1.1 POST /track_label" - 200 OK
10.5.24.119:53428 - - [28/May/2020 13:11:27] "HTTP/1.1 POST /track_label" - 200 OK
10.5.24.119:53558 - - [28/May/2020 13:12:32] "HTTP/1.1 POST /track_label" - 200 OK
10.5.24.119:53686 - - [28/May/2020 13:13:37] "HTTP/1.1 POST /track_label" - 200 OK
10.5.24.119:53818 - - [28/May/2020 13:14:42] "HTTP/1.1 POST /track_label" - 200 OK
10.5.24.119:53948 - - [28/May/2020 13:15:47] "HTTP/1.1 POST /track_label" - 200 OK
10.5.24.119:54082 - - [28/May/2020 13:16:52] "HTTP/1.1 POST /track_label" - 200 OK
10.5.24.119:54214 - - [28/May/2020 13:17:57] "HTTP/1.1 POST /track_label" - 200 OK
10.5.24.119:54344 - - [28/May/2020 13:19:02] "HTTP/1.1 POST /track_label" - 200 OK
10.5.24.119:54476 - - [28/May/2020 13:20:07] "HTTP/1.1 POST /track_label" - 200 OK
10.5.24.119:54606 - - [28/May/2020 13:21:12] "HTTP/1.1 POST /track_label" - 200 OK
10.5.24.119:54738 - - [28/May/2020 13:22:17] "HTTP/1.1 POST /track_label" - 200 OK
10.5.24.119:54868 - - [28/May/2020 13:23:22] "HTTP/1.1 POST /track_label" - 200 OK
10.5.24.119:55000 - - [28/May/2020 13:24:27] "HTTP/1.1 POST /track_label" - 200 OK
10.5.24.119:55134 - - [28/May/2020 13:25:32] "HTTP/1.1 POST /track_label" - 200 OK
10.5.24.119:55264 - - [28/May/2020 13:26:37] "HTTP/1.1 POST /track_label" - 200 OK
10.5.24.119:55396 - - [28/May/2020 13:27:42] "HTTP/1.1 POST /track_label" - 200 OK
10.5.24.119:55524 - - [28/May/2020 13:28:47] "HTTP/1.1 POST /track_label" - 200 OK
10.5.24.119:55656 - - [28/May/2020 13:29:52] "HTTP/1.1 POST /track_label" - 200 OK
10.5.24.119:55784 - - [28/May/2020 13:30:57] "HTTP/1.1 POST /track_label" - 200 OK
10.5.24.119:55916 - - [28/May/2020 13:32:02] "HTTP/1.1 POST /track_label" - 200 OK
10.5.24.119:56046 - - [28/May/2020 13:33:07] "HTTP/1.1 POST /track_label" - 200 OK
10.5.24.119:56178 - - [28/May/2020 13:34:12] "HTTP/1.1 POST /track_label" - 200 OK
10.5.24.119:56308 - - [28/May/2020 13:35:17] "HTTP/1.1 POST /track_label" - 200 OK
10.5.24.119:56438 - - [28/May/2020 13:36:22] "HTTP/1.1 POST /track_label" - 200 OK
10.5.24.119:56570 - - [28/May/2020 13:37:27] "HTTP/1.1 POST /track_label" - 200 OK
10.5.24.119:56704 - - [28/May/2020 13:38:32] "HTTP/1.1 POST /track_label" - 200 OK
10.5.24.119:56836 - - [28/May/2020 13:39:37] "HTTP/1.1 POST /track_label" - 200 OK
10.5.24.119:56964 - - [28/May/2020 13:40:42] "HTTP/1.1 POST /track_label" - 200 OK
10.5.24.119:57096 - - [28/May/2020 13:41:47] "HTTP/1.1 POST /track_label" - 200 OK
10.5.24.119:57226 - - [28/May/2020 13:42:52] "HTTP/1.1 POST /track_label" - 200 OK
10.5.24.119:57360 - - [28/May/2020 13:43:57] "HTTP/1.1 POST /track_label" - 200 OK
10.5.24.119:57490 - - [28/May/2020 13:45:02] "HTTP/1.1 POST /track_label" - 200 OK
10.5.24.119:57622 - - [28/May/2020 13:46:07] "HTTP/1.1 POST /track_label" - 200 OK
10.5.24.119:57754 - - [28/May/2020 13:47:12] "HTTP/1.1 POST /track_label" - 200 OK
10.0.105.85:49372 - - [29/May/2020 01:09:59] "HTTP/1.1 POST /track_label" - 200 OK
10.5.24.119:59148 - - [29/May/2020 01:21:12] "HTTP/1.1 POST /track_label" - 200 OK
10.5.24.119:59280 - - [29/May/2020 01:22:17] "HTTP/1.1 POST /track_label" - 200 OK
10.5.24.119:59414 - - [29/May/2020 01:23:22] "HTTP/1.1 POST /track_label" - 200 OK
10.5.24.119:59548 - - [29/May/2020 01:24:27] "HTTP/1.1 POST /track_label" - 200 OK
10.5.24.119:59678 - - [29/May/2020 01:25:32] "HTTP/1.1 POST /track_label" - 200 OK
10.5.24.119:59810 - - [29/May/2020 01:26:37] "HTTP/1.1 POST /track_label" - 200 OK
10.5.24.119:59942 - - [29/May/2020 01:27:42] "HTTP/1.1 POST /track_label" - 200 OK
10.5.24.119:60072 - - [29/May/2020 01:28:47] "HTTP/1.1 POST /track_label" - 200 OK
10.5.24.119:60206 - - [29/May/2020 01:29:52] "HTTP/1.1 POST /track_label" - 200 OK
10.5.24.119:60334 - - [29/May/2020 01:30:57] "HTTP/1.1 POST /track_label" - 200 OK
10.5.24.119:60466 - - [29/May/2020 01:32:02] "HTTP/1.1 POST /track_label" - 200 OK
10.5.24.119:60594 - - [29/May/2020 01:33:07] "HTTP/1.1 POST /track_label" - 200 OK
10.5.24.119:60724 - - [29/May/2020 01:34:12] "HTTP/1.1 POST /track_label" - 200 OK
10.5.24.119:60858 - - [29/May/2020 01:35:17] "HTTP/1.1 POST /track_label" - 200 OK
10.5.24.119:60996 - - [29/May/2020 01:36:22] "HTTP/1.1 POST /track_label" - 200 OK
10.5.24.119:32894 - - [29/May/2020 01:37:27] "HTTP/1.1 POST /track_label" - 200 OK
10.5.24.119:33024 - - [29/May/2020 01:38:32] "HTTP/1.1 POST /track_label" - 200 OK
10.5.24.119:33154 - - [29/May/2020 01:39:37] "HTTP/1.1 POST /track_label" - 200 OK
10.5.24.119:33282 - - [29/May/2020 01:40:42] "HTTP/1.1 POST /track_label" - 200 OK
10.5.24.119:33414 - - [29/May/2020 01:41:47] "HTTP/1.1 POST /track_label" - 200 OK
10.5.24.119:33546 - - [29/May/2020 01:42:52] "HTTP/1.1 POST /track_label" - 200 OK
10.5.24.119:33676 - - [29/May/2020 01:43:57] "HTTP/1.1 POST /track_label" - 200 OK
10.5.24.119:33806 - - [29/May/2020 01:45:02] "HTTP/1.1 POST /track_label" - 200 OK
10.5.24.119:33936 - - [29/May/2020 01:46:07] "HTTP/1.1 POST /track_label" - 200 OK
10.5.24.119:34068 - - [29/May/2020 01:47:12] "HTTP/1.1 POST /track_label" - 200 OK
10.5.24.119:34196 - - [29/May/2020 01:48:17] "HTTP/1.1 POST /track_label" - 200 OK
10.5.24.119:34326 - - [29/May/2020 01:49:22] "HTTP/1.1 POST /track_label" - 200 OK
10.5.24.119:34456 - - [29/May/2020 01:50:27] "HTTP/1.1 POST /track_label" - 200 OK
10.5.24.119:34588 - - [29/May/2020 01:51:32] "HTTP/1.1 POST /track_label" - 200 OK
10.5.24.119:34722 - - [29/May/2020 01:52:37] "HTTP/1.1 POST /track_label" - 200 OK
10.5.24.119:34856 - - [29/May/2020 01:53:42] "HTTP/1.1 POST /track_label" - 200 OK
10.5.24.119:34986 - - [29/May/2020 01:54:47] "HTTP/1.1 POST /track_label" - 200 OK
10.5.24.119:35116 - - [29/May/2020 01:55:52] "HTTP/1.1 POST /track_label" - 200 OK
10.5.24.119:35246 - - [29/May/2020 01:56:57] "HTTP/1.1 POST /track_label" - 200 OK
10.5.24.119:35374 - - [29/May/2020 01:58:02] "HTTP/1.1 POST /track_label" - 200 OK
10.5.24.119:35504 - - [29/May/2020 01:59:07] "HTTP/1.1 POST /track_label" - 200 OK
10.5.24.119:35636 - - [29/May/2020 02:00:12] "HTTP/1.1 POST /track_label" - 200 OK
10.5.24.119:35770 - - [29/May/2020 02:01:17] "HTTP/1.1 POST /track_label" - 200 OK
10.5.24.119:35902 - - [29/May/2020 02:02:22] "HTTP/1.1 POST /track_label" - 200 OK
10.5.24.119:36034 - - [29/May/2020 02:03:27] "HTTP/1.1 POST /track_label" - 200 OK
10.5.24.119:36166 - - [29/May/2020 02:04:32] "HTTP/1.1 POST /track_label" - 200 OK
10.5.24.119:36298 - - [29/May/2020 02:05:37] "HTTP/1.1 POST /track_label" - 200 OK
10.5.24.119:36428 - - [29/May/2020 02:06:42] "HTTP/1.1 POST /track_label" - 200 OK
10.5.24.119:36560 - - [29/May/2020 02:07:47] "HTTP/1.1 POST /track_label" - 200 OK
10.5.24.119:36690 - - [29/May/2020 02:08:52] "HTTP/1.1 POST /track_label" - 200 OK
Traceback (most recent call last):
  File "/root/anaconda3/envs/oneflow/lib/python3.5/site-packages/web/application.py", line 288, in process
    return p(lambda: process(processors))
  File "/root/anaconda3/envs/oneflow/lib/python3.5/site-packages/web/application.py", line 699, in processor
    h()
  File "/root/anaconda3/envs/oneflow/lib/python3.5/site-packages/web/application.py", line 805, in __call__
    self.check(mod)
  File "/root/anaconda3/envs/oneflow/lib/python3.5/site-packages/web/application.py", line 826, in check
    reload(mod)
  File "/root/anaconda3/envs/oneflow/lib/python3.5/importlib/__init__.py", line 166, in reload
    _bootstrap._exec(spec, module)
  File "<frozen importlib._bootstrap>", line 607, in _exec
AttributeError: 'NoneType' object has no attribute 'name'

Traceback (most recent call last):
  File "/root/anaconda3/envs/oneflow/lib/python3.5/site-packages/web/application.py", line 288, in process
    return p(lambda: process(processors))
  File "/root/anaconda3/envs/oneflow/lib/python3.5/site-packages/web/application.py", line 699, in processor
    h()
  File "/root/anaconda3/envs/oneflow/lib/python3.5/site-packages/web/application.py", line 805, in __call__
    self.check(mod)
  File "/root/anaconda3/envs/oneflow/lib/python3.5/site-packages/web/application.py", line 826, in check
    reload(mod)
  File "/root/anaconda3/envs/oneflow/lib/python3.5/importlib/__init__.py", line 166, in reload
    _bootstrap._exec(spec, module)
  File "<frozen importlib._bootstrap>", line 607, in _exec
AttributeError: 'NoneType' object has no attribute 'name'

During handling of the above exception, another exception occurred:

Traceback (most recent call last):
  File "/root/anaconda3/envs/oneflow/lib/python3.5/site-packages/web/application.py", line 288, in process
    return p(lambda: process(processors))
  File "/root/anaconda3/envs/oneflow/lib/python3.5/site-packages/web/application.py", line 717, in processor
    result = handler()
  File "/root/anaconda3/envs/oneflow/lib/python3.5/site-packages/web/application.py", line 288, in <lambda>
    return p(lambda: process(processors))
  File "/root/anaconda3/envs/oneflow/lib/python3.5/site-packages/web/application.py", line 297, in process
    raise self.internalerror()
  File "/root/anaconda3/envs/oneflow/lib/python3.5/site-packages/web/application.py", line 588, in internalerror
    return debugerror()
  File "/root/anaconda3/envs/oneflow/lib/python3.5/site-packages/web/debugerror.py", line 337, in debugerror
    return web._InternalError(djangoerror())
  File "/root/anaconda3/envs/oneflow/lib/python3.5/site-packages/web/debugerror.py", line 315, in djangoerror
    djangoerror_r = Template(djangoerror_t, filename=__file__, filter=websafe)
  File "/root/anaconda3/envs/oneflow/lib/python3.5/site-packages/web/template.py", line 943, in __init__
    code = self.compile_template(text, filename)
  File "/root/anaconda3/envs/oneflow/lib/python3.5/site-packages/web/template.py", line 1020, in compile_template
    compiled_code = compile(code, filename, "exec")
  File "/root/anaconda3/envs/oneflow/lib/python3.5/site-packages/web/debugerror.py", line 8
    def with (exception_type, exception_value, frames)
           ^
SyntaxError: invalid syntax

Template traceback:
    File '/root/anaconda3/envs/oneflow/lib/python3.5/site-packages/web/debugerror.py', line 8
        http://www.xfree86.org/3.3.6/COPYRIGHT2.html#5

Traceback (most recent call last):
  File "/root/anaconda3/envs/oneflow/lib/python3.5/site-packages/web/application.py", line 288, in process
    return p(lambda: process(processors))
  File "/root/anaconda3/envs/oneflow/lib/python3.5/site-packages/web/application.py", line 699, in processor
    h()
  File "/root/anaconda3/envs/oneflow/lib/python3.5/site-packages/web/application.py", line 805, in __call__
    self.check(mod)
  File "/root/anaconda3/envs/oneflow/lib/python3.5/site-packages/web/application.py", line 826, in check
    reload(mod)
  File "/root/anaconda3/envs/oneflow/lib/python3.5/importlib/__init__.py", line 166, in reload
    _bootstrap._exec(spec, module)
  File "<frozen importlib._bootstrap>", line 607, in _exec
AttributeError: 'NoneType' object has no attribute 'name'

During handling of the above exception, another exception occurred:

Traceback (most recent call last):
  File "/root/anaconda3/envs/oneflow/lib/python3.5/site-packages/web/application.py", line 288, in process
    return p(lambda: process(processors))
  File "/root/anaconda3/envs/oneflow/lib/python3.5/site-packages/web/application.py", line 717, in processor
    result = handler()
  File "/root/anaconda3/envs/oneflow/lib/python3.5/site-packages/web/application.py", line 288, in <lambda>
    return p(lambda: process(processors))
  File "/root/anaconda3/envs/oneflow/lib/python3.5/site-packages/web/application.py", line 297, in process
    raise self.internalerror()
  File "/root/anaconda3/envs/oneflow/lib/python3.5/site-packages/web/application.py", line 588, in internalerror
    return debugerror()
  File "/root/anaconda3/envs/oneflow/lib/python3.5/site-packages/web/debugerror.py", line 337, in debugerror
    return web._InternalError(djangoerror())
  File "/root/anaconda3/envs/oneflow/lib/python3.5/site-packages/web/debugerror.py", line 315, in djangoerror
    djangoerror_r = Template(djangoerror_t, filename=__file__, filter=websafe)
  File "/root/anaconda3/envs/oneflow/lib/python3.5/site-packages/web/template.py", line 943, in __init__
    code = self.compile_template(text, filename)
  File "/root/anaconda3/envs/oneflow/lib/python3.5/site-packages/web/template.py", line 1020, in compile_template
    compiled_code = compile(code, filename, "exec")
  File "/root/anaconda3/envs/oneflow/lib/python3.5/site-packages/web/debugerror.py", line 8
    def with (exception_type, exception_value, frames)
           ^
SyntaxError: invalid syntax

Template traceback:
    File '/root/anaconda3/envs/oneflow/lib/python3.5/site-packages/web/debugerror.py', line 8
        http://www.xfree86.org/3.3.6/COPYRIGHT2.html#5

During handling of the above exception, another exception occurred:

Traceback (most recent call last):
  File "/root/anaconda3/envs/oneflow/lib/python3.5/site-packages/web/application.py", line 288, in process
    return p(lambda: process(processors))
  File "/root/anaconda3/envs/oneflow/lib/python3.5/site-packages/web/application.py", line 700, in processor
    return handler()
  File "/root/anaconda3/envs/oneflow/lib/python3.5/site-packages/web/application.py", line 288, in <lambda>
    return p(lambda: process(processors))
  File "/root/anaconda3/envs/oneflow/lib/python3.5/site-packages/web/application.py", line 297, in process
    raise self.internalerror()
  File "/root/anaconda3/envs/oneflow/lib/python3.5/site-packages/web/application.py", line 588, in internalerror
    return debugerror()
  File "/root/anaconda3/envs/oneflow/lib/python3.5/site-packages/web/debugerror.py", line 337, in debugerror
    return web._InternalError(djangoerror())
  File "/root/anaconda3/envs/oneflow/lib/python3.5/site-packages/web/debugerror.py", line 315, in djangoerror
    djangoerror_r = Template(djangoerror_t, filename=__file__, filter=websafe)
  File "/root/anaconda3/envs/oneflow/lib/python3.5/site-packages/web/template.py", line 943, in __init__
    code = self.compile_template(text, filename)
  File "/root/anaconda3/envs/oneflow/lib/python3.5/site-packages/web/template.py", line 1020, in compile_template
    compiled_code = compile(code, filename, "exec")
  File "/root/anaconda3/envs/oneflow/lib/python3.5/site-packages/web/debugerror.py", line 8
    def with (exception_type, exception_value, frames)
           ^
SyntaxError: invalid syntax

Template traceback:
    File '/root/anaconda3/envs/oneflow/lib/python3.5/site-packages/web/debugerror.py', line 8
        http://www.xfree86.org/3.3.6/COPYRIGHT2.html#5

SyntaxError('invalid syntax', ('/root/anaconda3/envs/oneflow/lib/python3.5/site-packages/web/debugerror.py', 8, 12, '    def with (exception_type, exception_value, frames)\n'))
Traceback (most recent call last):
  File "/root/anaconda3/envs/oneflow/lib/python3.5/site-packages/web/application.py", line 288, in process
    return p(lambda: process(processors))
  File "/root/anaconda3/envs/oneflow/lib/python3.5/site-packages/web/application.py", line 699, in processor
    h()
  File "/root/anaconda3/envs/oneflow/lib/python3.5/site-packages/web/application.py", line 805, in __call__
    self.check(mod)
  File "/root/anaconda3/envs/oneflow/lib/python3.5/site-packages/web/application.py", line 826, in check
    reload(mod)
  File "/root/anaconda3/envs/oneflow/lib/python3.5/importlib/__init__.py", line 166, in reload
    _bootstrap._exec(spec, module)
  File "<frozen importlib._bootstrap>", line 607, in _exec
AttributeError: 'NoneType' object has no attribute 'name'

During handling of the above exception, another exception occurred:

Traceback (most recent call last):
  File "/root/anaconda3/envs/oneflow/lib/python3.5/site-packages/web/application.py", line 288, in process
    return p(lambda: process(processors))
  File "/root/anaconda3/envs/oneflow/lib/python3.5/site-packages/web/application.py", line 717, in processor
    result = handler()
  File "/root/anaconda3/envs/oneflow/lib/python3.5/site-packages/web/application.py", line 288, in <lambda>
    return p(lambda: process(processors))
  File "/root/anaconda3/envs/oneflow/lib/python3.5/site-packages/web/application.py", line 297, in process
    raise self.internalerror()
  File "/root/anaconda3/envs/oneflow/lib/python3.5/site-packages/web/application.py", line 588, in internalerror
    return debugerror()
  File "/root/anaconda3/envs/oneflow/lib/python3.5/site-packages/web/debugerror.py", line 337, in debugerror
    return web._InternalError(djangoerror())
  File "/root/anaconda3/envs/oneflow/lib/python3.5/site-packages/web/debugerror.py", line 315, in djangoerror
    djangoerror_r = Template(djangoerror_t, filename=__file__, filter=websafe)
  File "/root/anaconda3/envs/oneflow/lib/python3.5/site-packages/web/template.py", line 943, in __init__
    code = self.compile_template(text, filename)
  File "/root/anaconda3/envs/oneflow/lib/python3.5/site-packages/web/template.py", line 1020, in compile_template
    compiled_code = compile(code, filename, "exec")
  File "/root/anaconda3/envs/oneflow/lib/python3.5/site-packages/web/debugerror.py", line 8
    def with (exception_type, exception_value, frames)
           ^
SyntaxError: invalid syntax

Template traceback:
    File '/root/anaconda3/envs/oneflow/lib/python3.5/site-packages/web/debugerror.py', line 8
        http://www.xfree86.org/3.3.6/COPYRIGHT2.html#5

During handling of the above exception, another exception occurred:

Traceback (most recent call last):
  File "/root/anaconda3/envs/oneflow/lib/python3.5/site-packages/web/application.py", line 288, in process
    return p(lambda: process(processors))
  File "/root/anaconda3/envs/oneflow/lib/python3.5/site-packages/web/application.py", line 700, in processor
    return handler()
  File "/root/anaconda3/envs/oneflow/lib/python3.5/site-packages/web/application.py", line 288, in <lambda>
    return p(lambda: process(processors))
  File "/root/anaconda3/envs/oneflow/lib/python3.5/site-packages/web/application.py", line 297, in process
    raise self.internalerror()
  File "/root/anaconda3/envs/oneflow/lib/python3.5/site-packages/web/application.py", line 588, in internalerror
    return debugerror()
  File "/root/anaconda3/envs/oneflow/lib/python3.5/site-packages/web/debugerror.py", line 337, in debugerror
    return web._InternalError(djangoerror())
  File "/root/anaconda3/envs/oneflow/lib/python3.5/site-packages/web/debugerror.py", line 315, in djangoerror
    djangoerror_r = Template(djangoerror_t, filename=__file__, filter=websafe)
  File "/root/anaconda3/envs/oneflow/lib/python3.5/site-packages/web/template.py", line 943, in __init__
    code = self.compile_template(text, filename)
  File "/root/anaconda3/envs/oneflow/lib/python3.5/site-packages/web/template.py", line 1020, in compile_template
    compiled_code = compile(code, filename, "exec")
  File "/root/anaconda3/envs/oneflow/lib/python3.5/site-packages/web/debugerror.py", line 8
    def with (exception_type, exception_value, frames)
           ^
SyntaxError: invalid syntax

Template traceback:
    File '/root/anaconda3/envs/oneflow/lib/python3.5/site-packages/web/debugerror.py', line 8
        http://www.xfree86.org/3.3.6/COPYRIGHT2.html#5

During handling of the above exception, another exception occurred:

Traceback (most recent call last):
  File "/root/anaconda3/envs/oneflow/lib/python3.5/site-packages/cheroot/server.py", line 1269, in communicate
    req.respond()
  File "/root/anaconda3/envs/oneflow/lib/python3.5/site-packages/cheroot/server.py", line 1071, in respond
    self.server.gateway(self).respond()
  File "/root/anaconda3/envs/oneflow/lib/python3.5/site-packages/cheroot/wsgi.py", line 143, in respond
    response = self.req.server.wsgi_app(self.env, self.start_response)
  File "/root/anaconda3/envs/oneflow/lib/python3.5/site-packages/web/httpserver.py", line 306, in __call__
    return self.app(environ, xstart_response)
  File "/root/anaconda3/envs/oneflow/lib/python3.5/site-packages/web/httpserver.py", line 273, in __call__
    return self.app(environ, start_response)
  File "/root/anaconda3/envs/oneflow/lib/python3.5/site-packages/web/application.py", line 329, in wsgi
    result = self.handle_with_processors()
  File "/root/anaconda3/envs/oneflow/lib/python3.5/site-packages/web/application.py", line 300, in handle_with_processors
    return process(self.processors)
  File "/root/anaconda3/envs/oneflow/lib/python3.5/site-packages/web/application.py", line 297, in process
    raise self.internalerror()
  File "/root/anaconda3/envs/oneflow/lib/python3.5/site-packages/web/application.py", line 588, in internalerror
    return debugerror()
  File "/root/anaconda3/envs/oneflow/lib/python3.5/site-packages/web/debugerror.py", line 337, in debugerror
    return web._InternalError(djangoerror())
  File "/root/anaconda3/envs/oneflow/lib/python3.5/site-packages/web/debugerror.py", line 315, in djangoerror
    djangoerror_r = Template(djangoerror_t, filename=__file__, filter=websafe)
  File "/root/anaconda3/envs/oneflow/lib/python3.5/site-packages/web/template.py", line 943, in __init__
    code = self.compile_template(text, filename)
  File "/root/anaconda3/envs/oneflow/lib/python3.5/site-packages/web/template.py", line 1020, in compile_template
    compiled_code = compile(code, filename, "exec")
  File "/root/anaconda3/envs/oneflow/lib/python3.5/site-packages/web/debugerror.py", line 8
    def with (exception_type, exception_value, frames)
           ^
SyntaxError: invalid syntax

Template traceback:
    File '/root/anaconda3/envs/oneflow/lib/python3.5/site-packages/web/debugerror.py', line 8
        http://www.xfree86.org/3.3.6/COPYRIGHT2.html#5
Traceback (most recent call last):
  File "/root/anaconda3/envs/oneflow/lib/python3.5/site-packages/web/application.py", line 288, in process
    return p(lambda: process(processors))
  File "/root/anaconda3/envs/oneflow/lib/python3.5/site-packages/web/application.py", line 699, in processor
    h()
  File "/root/anaconda3/envs/oneflow/lib/python3.5/site-packages/web/application.py", line 805, in __call__
    self.check(mod)
  File "/root/anaconda3/envs/oneflow/lib/python3.5/site-packages/web/application.py", line 826, in check
    reload(mod)
  File "/root/anaconda3/envs/oneflow/lib/python3.5/importlib/__init__.py", line 166, in reload
    _bootstrap._exec(spec, module)
  File "<frozen importlib._bootstrap>", line 607, in _exec
AttributeError: 'NoneType' object has no attribute 'name'

Traceback (most recent call last):
  File "/root/anaconda3/envs/oneflow/lib/python3.5/site-packages/web/application.py", line 288, in process
    return p(lambda: process(processors))
  File "/root/anaconda3/envs/oneflow/lib/python3.5/site-packages/web/application.py", line 699, in processor
    h()
  File "/root/anaconda3/envs/oneflow/lib/python3.5/site-packages/web/application.py", line 805, in __call__
    self.check(mod)
  File "/root/anaconda3/envs/oneflow/lib/python3.5/site-packages/web/application.py", line 826, in check
    reload(mod)
  File "/root/anaconda3/envs/oneflow/lib/python3.5/importlib/__init__.py", line 166, in reload
    _bootstrap._exec(spec, module)
  File "<frozen importlib._bootstrap>", line 607, in _exec
AttributeError: 'NoneType' object has no attribute 'name'

During handling of the above exception, another exception occurred:

Traceback (most recent call last):
  File "/root/anaconda3/envs/oneflow/lib/python3.5/site-packages/web/application.py", line 288, in process
    return p(lambda: process(processors))
  File "/root/anaconda3/envs/oneflow/lib/python3.5/site-packages/web/application.py", line 717, in processor
    result = handler()
  File "/root/anaconda3/envs/oneflow/lib/python3.5/site-packages/web/application.py", line 288, in <lambda>
    return p(lambda: process(processors))
  File "/root/anaconda3/envs/oneflow/lib/python3.5/site-packages/web/application.py", line 297, in process
    raise self.internalerror()
  File "/root/anaconda3/envs/oneflow/lib/python3.5/site-packages/web/application.py", line 588, in internalerror
    return debugerror()
  File "/root/anaconda3/envs/oneflow/lib/python3.5/site-packages/web/debugerror.py", line 337, in debugerror
    return web._InternalError(djangoerror())
  File "/root/anaconda3/envs/oneflow/lib/python3.5/site-packages/web/debugerror.py", line 315, in djangoerror
    djangoerror_r = Template(djangoerror_t, filename=__file__, filter=websafe)
  File "/root/anaconda3/envs/oneflow/lib/python3.5/site-packages/web/template.py", line 943, in __init__
    code = self.compile_template(text, filename)
  File "/root/anaconda3/envs/oneflow/lib/python3.5/site-packages/web/template.py", line 1020, in compile_template
    compiled_code = compile(code, filename, "exec")
  File "/root/anaconda3/envs/oneflow/lib/python3.5/site-packages/web/debugerror.py", line 8
    def with (exception_type, exception_value, frames)
           ^
SyntaxError: invalid syntax

Template traceback:
    File '/root/anaconda3/envs/oneflow/lib/python3.5/site-packages/web/debugerror.py', line 8
        http://www.xfree86.org/3.3.6/COPYRIGHT2.html#5

Traceback (most recent call last):
  File "/root/anaconda3/envs/oneflow/lib/python3.5/site-packages/web/application.py", line 288, in process
    return p(lambda: process(processors))
  File "/root/anaconda3/envs/oneflow/lib/python3.5/site-packages/web/application.py", line 699, in processor
    h()
  File "/root/anaconda3/envs/oneflow/lib/python3.5/site-packages/web/application.py", line 805, in __call__
    self.check(mod)
  File "/root/anaconda3/envs/oneflow/lib/python3.5/site-packages/web/application.py", line 826, in check
    reload(mod)
  File "/root/anaconda3/envs/oneflow/lib/python3.5/importlib/__init__.py", line 166, in reload
    _bootstrap._exec(spec, module)
  File "<frozen importlib._bootstrap>", line 607, in _exec
AttributeError: 'NoneType' object has no attribute 'name'

During handling of the above exception, another exception occurred:

Traceback (most recent call last):
  File "/root/anaconda3/envs/oneflow/lib/python3.5/site-packages/web/application.py", line 288, in process
    return p(lambda: process(processors))
  File "/root/anaconda3/envs/oneflow/lib/python3.5/site-packages/web/application.py", line 717, in processor
    result = handler()
  File "/root/anaconda3/envs/oneflow/lib/python3.5/site-packages/web/application.py", line 288, in <lambda>
    return p(lambda: process(processors))
  File "/root/anaconda3/envs/oneflow/lib/python3.5/site-packages/web/application.py", line 297, in process
    raise self.internalerror()
  File "/root/anaconda3/envs/oneflow/lib/python3.5/site-packages/web/application.py", line 588, in internalerror
    return debugerror()
  File "/root/anaconda3/envs/oneflow/lib/python3.5/site-packages/web/debugerror.py", line 337, in debugerror
    return web._InternalError(djangoerror())
  File "/root/anaconda3/envs/oneflow/lib/python3.5/site-packages/web/debugerror.py", line 315, in djangoerror
    djangoerror_r = Template(djangoerror_t, filename=__file__, filter=websafe)
  File "/root/anaconda3/envs/oneflow/lib/python3.5/site-packages/web/template.py", line 943, in __init__
    code = self.compile_template(text, filename)
  File "/root/anaconda3/envs/oneflow/lib/python3.5/site-packages/web/template.py", line 1020, in compile_template
    compiled_code = compile(code, filename, "exec")
  File "/root/anaconda3/envs/oneflow/lib/python3.5/site-packages/web/debugerror.py", line 8
    def with (exception_type, exception_value, frames)
           ^
SyntaxError: invalid syntax

Template traceback:
    File '/root/anaconda3/envs/oneflow/lib/python3.5/site-packages/web/debugerror.py', line 8
        http://www.xfree86.org/3.3.6/COPYRIGHT2.html#5

During handling of the above exception, another exception occurred:

Traceback (most recent call last):
  File "/root/anaconda3/envs/oneflow/lib/python3.5/site-packages/web/application.py", line 288, in process
    return p(lambda: process(processors))
  File "/root/anaconda3/envs/oneflow/lib/python3.5/site-packages/web/application.py", line 700, in processor
    return handler()
  File "/root/anaconda3/envs/oneflow/lib/python3.5/site-packages/web/application.py", line 288, in <lambda>
    return p(lambda: process(processors))
  File "/root/anaconda3/envs/oneflow/lib/python3.5/site-packages/web/application.py", line 297, in process
    raise self.internalerror()
  File "/root/anaconda3/envs/oneflow/lib/python3.5/site-packages/web/application.py", line 588, in internalerror
    return debugerror()
  File "/root/anaconda3/envs/oneflow/lib/python3.5/site-packages/web/debugerror.py", line 337, in debugerror
    return web._InternalError(djangoerror())
  File "/root/anaconda3/envs/oneflow/lib/python3.5/site-packages/web/debugerror.py", line 315, in djangoerror
    djangoerror_r = Template(djangoerror_t, filename=__file__, filter=websafe)
  File "/root/anaconda3/envs/oneflow/lib/python3.5/site-packages/web/template.py", line 943, in __init__
    code = self.compile_template(text, filename)
  File "/root/anaconda3/envs/oneflow/lib/python3.5/site-packages/web/template.py", line 1020, in compile_template
    compiled_code = compile(code, filename, "exec")
  File "/root/anaconda3/envs/oneflow/lib/python3.5/site-packages/web/debugerror.py", line 8
    def with (exception_type, exception_value, frames)
           ^
SyntaxError: invalid syntax

Template traceback:
    File '/root/anaconda3/envs/oneflow/lib/python3.5/site-packages/web/debugerror.py', line 8
        http://www.xfree86.org/3.3.6/COPYRIGHT2.html#5

SyntaxError('invalid syntax', ('/root/anaconda3/envs/oneflow/lib/python3.5/site-packages/web/debugerror.py', 8, 12, '    def with (exception_type, exception_value, frames)\n'))
Traceback (most recent call last):
  File "/root/anaconda3/envs/oneflow/lib/python3.5/site-packages/web/application.py", line 288, in process
    return p(lambda: process(processors))
  File "/root/anaconda3/envs/oneflow/lib/python3.5/site-packages/web/application.py", line 699, in processor
    h()
  File "/root/anaconda3/envs/oneflow/lib/python3.5/site-packages/web/application.py", line 805, in __call__
    self.check(mod)
  File "/root/anaconda3/envs/oneflow/lib/python3.5/site-packages/web/application.py", line 826, in check
    reload(mod)
  File "/root/anaconda3/envs/oneflow/lib/python3.5/importlib/__init__.py", line 166, in reload
    _bootstrap._exec(spec, module)
  File "<frozen importlib._bootstrap>", line 607, in _exec
AttributeError: 'NoneType' object has no attribute 'name'

During handling of the above exception, another exception occurred:

Traceback (most recent call last):
  File "/root/anaconda3/envs/oneflow/lib/python3.5/site-packages/web/application.py", line 288, in process
    return p(lambda: process(processors))
  File "/root/anaconda3/envs/oneflow/lib/python3.5/site-packages/web/application.py", line 717, in processor
    result = handler()
  File "/root/anaconda3/envs/oneflow/lib/python3.5/site-packages/web/application.py", line 288, in <lambda>
    return p(lambda: process(processors))
  File "/root/anaconda3/envs/oneflow/lib/python3.5/site-packages/web/application.py", line 297, in process
    raise self.internalerror()
  File "/root/anaconda3/envs/oneflow/lib/python3.5/site-packages/web/application.py", line 588, in internalerror
    return debugerror()
  File "/root/anaconda3/envs/oneflow/lib/python3.5/site-packages/web/debugerror.py", line 337, in debugerror
    return web._InternalError(djangoerror())
  File "/root/anaconda3/envs/oneflow/lib/python3.5/site-packages/web/debugerror.py", line 315, in djangoerror
    djangoerror_r = Template(djangoerror_t, filename=__file__, filter=websafe)
  File "/root/anaconda3/envs/oneflow/lib/python3.5/site-packages/web/template.py", line 943, in __init__
    code = self.compile_template(text, filename)
  File "/root/anaconda3/envs/oneflow/lib/python3.5/site-packages/web/template.py", line 1020, in compile_template
    compiled_code = compile(code, filename, "exec")
  File "/root/anaconda3/envs/oneflow/lib/python3.5/site-packages/web/debugerror.py", line 8
    def with (exception_type, exception_value, frames)
           ^
SyntaxError: invalid syntax

Template traceback:
    File '/root/anaconda3/envs/oneflow/lib/python3.5/site-packages/web/debugerror.py', line 8
        http://www.xfree86.org/3.3.6/COPYRIGHT2.html#5

During handling of the above exception, another exception occurred:

Traceback (most recent call last):
  File "/root/anaconda3/envs/oneflow/lib/python3.5/site-packages/web/application.py", line 288, in process
    return p(lambda: process(processors))
  File "/root/anaconda3/envs/oneflow/lib/python3.5/site-packages/web/application.py", line 700, in processor
    return handler()
  File "/root/anaconda3/envs/oneflow/lib/python3.5/site-packages/web/application.py", line 288, in <lambda>
    return p(lambda: process(processors))
  File "/root/anaconda3/envs/oneflow/lib/python3.5/site-packages/web/application.py", line 297, in process
    raise self.internalerror()
  File "/root/anaconda3/envs/oneflow/lib/python3.5/site-packages/web/application.py", line 588, in internalerror
    return debugerror()
  File "/root/anaconda3/envs/oneflow/lib/python3.5/site-packages/web/debugerror.py", line 337, in debugerror
    return web._InternalError(djangoerror())
  File "/root/anaconda3/envs/oneflow/lib/python3.5/site-packages/web/debugerror.py", line 315, in djangoerror
    djangoerror_r = Template(djangoerror_t, filename=__file__, filter=websafe)
  File "/root/anaconda3/envs/oneflow/lib/python3.5/site-packages/web/template.py", line 943, in __init__
    code = self.compile_template(text, filename)
  File "/root/anaconda3/envs/oneflow/lib/python3.5/site-packages/web/template.py", line 1020, in compile_template
    compiled_code = compile(code, filename, "exec")
  File "/root/anaconda3/envs/oneflow/lib/python3.5/site-packages/web/debugerror.py", line 8
    def with (exception_type, exception_value, frames)
           ^
SyntaxError: invalid syntax

Template traceback:
    File '/root/anaconda3/envs/oneflow/lib/python3.5/site-packages/web/debugerror.py', line 8
        http://www.xfree86.org/3.3.6/COPYRIGHT2.html#5

During handling of the above exception, another exception occurred:

Traceback (most recent call last):
  File "/root/anaconda3/envs/oneflow/lib/python3.5/site-packages/cheroot/server.py", line 1269, in communicate
    req.respond()
  File "/root/anaconda3/envs/oneflow/lib/python3.5/site-packages/cheroot/server.py", line 1071, in respond
    self.server.gateway(self).respond()
  File "/root/anaconda3/envs/oneflow/lib/python3.5/site-packages/cheroot/wsgi.py", line 143, in respond
    response = self.req.server.wsgi_app(self.env, self.start_response)
  File "/root/anaconda3/envs/oneflow/lib/python3.5/site-packages/web/httpserver.py", line 306, in __call__
    return self.app(environ, xstart_response)
  File "/root/anaconda3/envs/oneflow/lib/python3.5/site-packages/web/httpserver.py", line 273, in __call__
    return self.app(environ, start_response)
  File "/root/anaconda3/envs/oneflow/lib/python3.5/site-packages/web/application.py", line 329, in wsgi
    result = self.handle_with_processors()
  File "/root/anaconda3/envs/oneflow/lib/python3.5/site-packages/web/application.py", line 300, in handle_with_processors
    return process(self.processors)
  File "/root/anaconda3/envs/oneflow/lib/python3.5/site-packages/web/application.py", line 297, in process
    raise self.internalerror()
  File "/root/anaconda3/envs/oneflow/lib/python3.5/site-packages/web/application.py", line 588, in internalerror
    return debugerror()
  File "/root/anaconda3/envs/oneflow/lib/python3.5/site-packages/web/debugerror.py", line 337, in debugerror
    return web._InternalError(djangoerror())
  File "/root/anaconda3/envs/oneflow/lib/python3.5/site-packages/web/debugerror.py", line 315, in djangoerror
    djangoerror_r = Template(djangoerror_t, filename=__file__, filter=websafe)
  File "/root/anaconda3/envs/oneflow/lib/python3.5/site-packages/web/template.py", line 943, in __init__
    code = self.compile_template(text, filename)
  File "/root/anaconda3/envs/oneflow/lib/python3.5/site-packages/web/template.py", line 1020, in compile_template
    compiled_code = compile(code, filename, "exec")
  File "/root/anaconda3/envs/oneflow/lib/python3.5/site-packages/web/debugerror.py", line 8
    def with (exception_type, exception_value, frames)
           ^
SyntaxError: invalid syntax

Template traceback:
    File '/root/anaconda3/envs/oneflow/lib/python3.5/site-packages/web/debugerror.py', line 8
        http://www.xfree86.org/3.3.6/COPYRIGHT2.html#5
Traceback (most recent call last):
  File "/root/anaconda3/envs/oneflow/lib/python3.5/site-packages/web/application.py", line 288, in process
    return p(lambda: process(processors))
  File "/root/anaconda3/envs/oneflow/lib/python3.5/site-packages/web/application.py", line 699, in processor
    h()
  File "/root/anaconda3/envs/oneflow/lib/python3.5/site-packages/web/application.py", line 805, in __call__
    self.check(mod)
  File "/root/anaconda3/envs/oneflow/lib/python3.5/site-packages/web/application.py", line 826, in check
    reload(mod)
  File "/root/anaconda3/envs/oneflow/lib/python3.5/importlib/__init__.py", line 166, in reload
    _bootstrap._exec(spec, module)
  File "<frozen importlib._bootstrap>", line 607, in _exec
AttributeError: 'NoneType' object has no attribute 'name'

Traceback (most recent call last):
  File "/root/anaconda3/envs/oneflow/lib/python3.5/site-packages/web/application.py", line 288, in process
    return p(lambda: process(processors))
  File "/root/anaconda3/envs/oneflow/lib/python3.5/site-packages/web/application.py", line 699, in processor
    h()
  File "/root/anaconda3/envs/oneflow/lib/python3.5/site-packages/web/application.py", line 805, in __call__
    self.check(mod)
  File "/root/anaconda3/envs/oneflow/lib/python3.5/site-packages/web/application.py", line 826, in check
    reload(mod)
  File "/root/anaconda3/envs/oneflow/lib/python3.5/importlib/__init__.py", line 166, in reload
    _bootstrap._exec(spec, module)
  File "<frozen importlib._bootstrap>", line 607, in _exec
AttributeError: 'NoneType' object has no attribute 'name'

During handling of the above exception, another exception occurred:

Traceback (most recent call last):
  File "/root/anaconda3/envs/oneflow/lib/python3.5/site-packages/web/application.py", line 288, in process
    return p(lambda: process(processors))
  File "/root/anaconda3/envs/oneflow/lib/python3.5/site-packages/web/application.py", line 717, in processor
    result = handler()
  File "/root/anaconda3/envs/oneflow/lib/python3.5/site-packages/web/application.py", line 288, in <lambda>
    return p(lambda: process(processors))
  File "/root/anaconda3/envs/oneflow/lib/python3.5/site-packages/web/application.py", line 297, in process
    raise self.internalerror()
  File "/root/anaconda3/envs/oneflow/lib/python3.5/site-packages/web/application.py", line 588, in internalerror
    return debugerror()
  File "/root/anaconda3/envs/oneflow/lib/python3.5/site-packages/web/debugerror.py", line 337, in debugerror
    return web._InternalError(djangoerror())
  File "/root/anaconda3/envs/oneflow/lib/python3.5/site-packages/web/debugerror.py", line 315, in djangoerror
    djangoerror_r = Template(djangoerror_t, filename=__file__, filter=websafe)
  File "/root/anaconda3/envs/oneflow/lib/python3.5/site-packages/web/template.py", line 943, in __init__
    code = self.compile_template(text, filename)
  File "/root/anaconda3/envs/oneflow/lib/python3.5/site-packages/web/template.py", line 1020, in compile_template
    compiled_code = compile(code, filename, "exec")
  File "/root/anaconda3/envs/oneflow/lib/python3.5/site-packages/web/debugerror.py", line 8
    def with (exception_type, exception_value, frames)
           ^
SyntaxError: invalid syntax

Template traceback:
    File '/root/anaconda3/envs/oneflow/lib/python3.5/site-packages/web/debugerror.py', line 8
        http://www.xfree86.org/3.3.6/COPYRIGHT2.html#5

Traceback (most recent call last):
  File "/root/anaconda3/envs/oneflow/lib/python3.5/site-packages/web/application.py", line 288, in process
    return p(lambda: process(processors))
  File "/root/anaconda3/envs/oneflow/lib/python3.5/site-packages/web/application.py", line 699, in processor
    h()
  File "/root/anaconda3/envs/oneflow/lib/python3.5/site-packages/web/application.py", line 805, in __call__
    self.check(mod)
  File "/root/anaconda3/envs/oneflow/lib/python3.5/site-packages/web/application.py", line 826, in check
    reload(mod)
  File "/root/anaconda3/envs/oneflow/lib/python3.5/importlib/__init__.py", line 166, in reload
    _bootstrap._exec(spec, module)
  File "<frozen importlib._bootstrap>", line 607, in _exec
AttributeError: 'NoneType' object has no attribute 'name'

During handling of the above exception, another exception occurred:

Traceback (most recent call last):
  File "/root/anaconda3/envs/oneflow/lib/python3.5/site-packages/web/application.py", line 288, in process
    return p(lambda: process(processors))
  File "/root/anaconda3/envs/oneflow/lib/python3.5/site-packages/web/application.py", line 717, in processor
    result = handler()
  File "/root/anaconda3/envs/oneflow/lib/python3.5/site-packages/web/application.py", line 288, in <lambda>
    return p(lambda: process(processors))
  File "/root/anaconda3/envs/oneflow/lib/python3.5/site-packages/web/application.py", line 297, in process
    raise self.internalerror()
  File "/root/anaconda3/envs/oneflow/lib/python3.5/site-packages/web/application.py", line 588, in internalerror
    return debugerror()
  File "/root/anaconda3/envs/oneflow/lib/python3.5/site-packages/web/debugerror.py", line 337, in debugerror
    return web._InternalError(djangoerror())
  File "/root/anaconda3/envs/oneflow/lib/python3.5/site-packages/web/debugerror.py", line 315, in djangoerror
    djangoerror_r = Template(djangoerror_t, filename=__file__, filter=websafe)
  File "/root/anaconda3/envs/oneflow/lib/python3.5/site-packages/web/template.py", line 943, in __init__
    code = self.compile_template(text, filename)
  File "/root/anaconda3/envs/oneflow/lib/python3.5/site-packages/web/template.py", line 1020, in compile_template
    compiled_code = compile(code, filename, "exec")
  File "/root/anaconda3/envs/oneflow/lib/python3.5/site-packages/web/debugerror.py", line 8
    def with (exception_type, exception_value, frames)
           ^
SyntaxError: invalid syntax

Template traceback:
    File '/root/anaconda3/envs/oneflow/lib/python3.5/site-packages/web/debugerror.py', line 8
        http://www.xfree86.org/3.3.6/COPYRIGHT2.html#5

During handling of the above exception, another exception occurred:

Traceback (most recent call last):
  File "/root/anaconda3/envs/oneflow/lib/python3.5/site-packages/web/application.py", line 288, in process
    return p(lambda: process(processors))
  File "/root/anaconda3/envs/oneflow/lib/python3.5/site-packages/web/application.py", line 700, in processor
    return handler()
  File "/root/anaconda3/envs/oneflow/lib/python3.5/site-packages/web/application.py", line 288, in <lambda>
    return p(lambda: process(processors))
  File "/root/anaconda3/envs/oneflow/lib/python3.5/site-packages/web/application.py", line 297, in process
    raise self.internalerror()
  File "/root/anaconda3/envs/oneflow/lib/python3.5/site-packages/web/application.py", line 588, in internalerror
    return debugerror()
  File "/root/anaconda3/envs/oneflow/lib/python3.5/site-packages/web/debugerror.py", line 337, in debugerror
    return web._InternalError(djangoerror())
  File "/root/anaconda3/envs/oneflow/lib/python3.5/site-packages/web/debugerror.py", line 315, in djangoerror
    djangoerror_r = Template(djangoerror_t, filename=__file__, filter=websafe)
  File "/root/anaconda3/envs/oneflow/lib/python3.5/site-packages/web/template.py", line 943, in __init__
    code = self.compile_template(text, filename)
  File "/root/anaconda3/envs/oneflow/lib/python3.5/site-packages/web/template.py", line 1020, in compile_template
    compiled_code = compile(code, filename, "exec")
  File "/root/anaconda3/envs/oneflow/lib/python3.5/site-packages/web/debugerror.py", line 8
    def with (exception_type, exception_value, frames)
           ^
SyntaxError: invalid syntax

Template traceback:
    File '/root/anaconda3/envs/oneflow/lib/python3.5/site-packages/web/debugerror.py', line 8
        http://www.xfree86.org/3.3.6/COPYRIGHT2.html#5

SyntaxError('invalid syntax', ('/root/anaconda3/envs/oneflow/lib/python3.5/site-packages/web/debugerror.py', 8, 12, '    def with (exception_type, exception_value, frames)\n'))
Traceback (most recent call last):
  File "/root/anaconda3/envs/oneflow/lib/python3.5/site-packages/web/application.py", line 288, in process
    return p(lambda: process(processors))
  File "/root/anaconda3/envs/oneflow/lib/python3.5/site-packages/web/application.py", line 699, in processor
    h()
  File "/root/anaconda3/envs/oneflow/lib/python3.5/site-packages/web/application.py", line 805, in __call__
    self.check(mod)
  File "/root/anaconda3/envs/oneflow/lib/python3.5/site-packages/web/application.py", line 826, in check
    reload(mod)
  File "/root/anaconda3/envs/oneflow/lib/python3.5/importlib/__init__.py", line 166, in reload
    _bootstrap._exec(spec, module)
  File "<frozen importlib._bootstrap>", line 607, in _exec
AttributeError: 'NoneType' object has no attribute 'name'

During handling of the above exception, another exception occurred:

Traceback (most recent call last):
  File "/root/anaconda3/envs/oneflow/lib/python3.5/site-packages/web/application.py", line 288, in process
    return p(lambda: process(processors))
  File "/root/anaconda3/envs/oneflow/lib/python3.5/site-packages/web/application.py", line 717, in processor
    result = handler()
  File "/root/anaconda3/envs/oneflow/lib/python3.5/site-packages/web/application.py", line 288, in <lambda>
    return p(lambda: process(processors))
  File "/root/anaconda3/envs/oneflow/lib/python3.5/site-packages/web/application.py", line 297, in process
    raise self.internalerror()
  File "/root/anaconda3/envs/oneflow/lib/python3.5/site-packages/web/application.py", line 588, in internalerror
    return debugerror()
  File "/root/anaconda3/envs/oneflow/lib/python3.5/site-packages/web/debugerror.py", line 337, in debugerror
    return web._InternalError(djangoerror())
  File "/root/anaconda3/envs/oneflow/lib/python3.5/site-packages/web/debugerror.py", line 315, in djangoerror
    djangoerror_r = Template(djangoerror_t, filename=__file__, filter=websafe)
  File "/root/anaconda3/envs/oneflow/lib/python3.5/site-packages/web/template.py", line 943, in __init__
    code = self.compile_template(text, filename)
  File "/root/anaconda3/envs/oneflow/lib/python3.5/site-packages/web/template.py", line 1020, in compile_template
    compiled_code = compile(code, filename, "exec")
  File "/root/anaconda3/envs/oneflow/lib/python3.5/site-packages/web/debugerror.py", line 8
    def with (exception_type, exception_value, frames)
           ^
SyntaxError: invalid syntax

Template traceback:
    File '/root/anaconda3/envs/oneflow/lib/python3.5/site-packages/web/debugerror.py', line 8
        http://www.xfree86.org/3.3.6/COPYRIGHT2.html#5

During handling of the above exception, another exception occurred:

Traceback (most recent call last):
  File "/root/anaconda3/envs/oneflow/lib/python3.5/site-packages/web/application.py", line 288, in process
    return p(lambda: process(processors))
  File "/root/anaconda3/envs/oneflow/lib/python3.5/site-packages/web/application.py", line 700, in processor
    return handler()
  File "/root/anaconda3/envs/oneflow/lib/python3.5/site-packages/web/application.py", line 288, in <lambda>
    return p(lambda: process(processors))
  File "/root/anaconda3/envs/oneflow/lib/python3.5/site-packages/web/application.py", line 297, in process
    raise self.internalerror()
  File "/root/anaconda3/envs/oneflow/lib/python3.5/site-packages/web/application.py", line 588, in internalerror
    return debugerror()
  File "/root/anaconda3/envs/oneflow/lib/python3.5/site-packages/web/debugerror.py", line 337, in debugerror
    return web._InternalError(djangoerror())
  File "/root/anaconda3/envs/oneflow/lib/python3.5/site-packages/web/debugerror.py", line 315, in djangoerror
    djangoerror_r = Template(djangoerror_t, filename=__file__, filter=websafe)
  File "/root/anaconda3/envs/oneflow/lib/python3.5/site-packages/web/template.py", line 943, in __init__
    code = self.compile_template(text, filename)
  File "/root/anaconda3/envs/oneflow/lib/python3.5/site-packages/web/template.py", line 1020, in compile_template
    compiled_code = compile(code, filename, "exec")
  File "/root/anaconda3/envs/oneflow/lib/python3.5/site-packages/web/debugerror.py", line 8
    def with (exception_type, exception_value, frames)
           ^
SyntaxError: invalid syntax

Template traceback:
    File '/root/anaconda3/envs/oneflow/lib/python3.5/site-packages/web/debugerror.py', line 8
        http://www.xfree86.org/3.3.6/COPYRIGHT2.html#5

During handling of the above exception, another exception occurred:

Traceback (most recent call last):
  File "/root/anaconda3/envs/oneflow/lib/python3.5/site-packages/cheroot/server.py", line 1269, in communicate
    req.respond()
  File "/root/anaconda3/envs/oneflow/lib/python3.5/site-packages/cheroot/server.py", line 1071, in respond
    self.server.gateway(self).respond()
  File "/root/anaconda3/envs/oneflow/lib/python3.5/site-packages/cheroot/wsgi.py", line 143, in respond
    response = self.req.server.wsgi_app(self.env, self.start_response)
  File "/root/anaconda3/envs/oneflow/lib/python3.5/site-packages/web/httpserver.py", line 306, in __call__
    return self.app(environ, xstart_response)
  File "/root/anaconda3/envs/oneflow/lib/python3.5/site-packages/web/httpserver.py", line 273, in __call__
    return self.app(environ, start_response)
  File "/root/anaconda3/envs/oneflow/lib/python3.5/site-packages/web/application.py", line 329, in wsgi
    result = self.handle_with_processors()
  File "/root/anaconda3/envs/oneflow/lib/python3.5/site-packages/web/application.py", line 300, in handle_with_processors
    return process(self.processors)
  File "/root/anaconda3/envs/oneflow/lib/python3.5/site-packages/web/application.py", line 297, in process
    raise self.internalerror()
  File "/root/anaconda3/envs/oneflow/lib/python3.5/site-packages/web/application.py", line 588, in internalerror
    return debugerror()
  File "/root/anaconda3/envs/oneflow/lib/python3.5/site-packages/web/debugerror.py", line 337, in debugerror
    return web._InternalError(djangoerror())
  File "/root/anaconda3/envs/oneflow/lib/python3.5/site-packages/web/debugerror.py", line 315, in djangoerror
    djangoerror_r = Template(djangoerror_t, filename=__file__, filter=websafe)
  File "/root/anaconda3/envs/oneflow/lib/python3.5/site-packages/web/template.py", line 943, in __init__
    code = self.compile_template(text, filename)
  File "/root/anaconda3/envs/oneflow/lib/python3.5/site-packages/web/template.py", line 1020, in compile_template
    compiled_code = compile(code, filename, "exec")
  File "/root/anaconda3/envs/oneflow/lib/python3.5/site-packages/web/debugerror.py", line 8
    def with (exception_type, exception_value, frames)
           ^
SyntaxError: invalid syntax

Template traceback:
    File '/root/anaconda3/envs/oneflow/lib/python3.5/site-packages/web/debugerror.py', line 8
        http://www.xfree86.org/3.3.6/COPYRIGHT2.html#5
Traceback (most recent call last):
  File "/root/anaconda3/envs/oneflow/lib/python3.5/site-packages/web/application.py", line 288, in process
    return p(lambda: process(processors))
  File "/root/anaconda3/envs/oneflow/lib/python3.5/site-packages/web/application.py", line 699, in processor
    h()
  File "/root/anaconda3/envs/oneflow/lib/python3.5/site-packages/web/application.py", line 805, in __call__
    self.check(mod)
  File "/root/anaconda3/envs/oneflow/lib/python3.5/site-packages/web/application.py", line 826, in check
    reload(mod)
  File "/root/anaconda3/envs/oneflow/lib/python3.5/importlib/__init__.py", line 166, in reload
    _bootstrap._exec(spec, module)
  File "<frozen importlib._bootstrap>", line 607, in _exec
AttributeError: 'NoneType' object has no attribute 'name'

Traceback (most recent call last):
  File "/root/anaconda3/envs/oneflow/lib/python3.5/site-packages/web/application.py", line 288, in process
    return p(lambda: process(processors))
  File "/root/anaconda3/envs/oneflow/lib/python3.5/site-packages/web/application.py", line 699, in processor
    h()
  File "/root/anaconda3/envs/oneflow/lib/python3.5/site-packages/web/application.py", line 805, in __call__
    self.check(mod)
  File "/root/anaconda3/envs/oneflow/lib/python3.5/site-packages/web/application.py", line 826, in check
    reload(mod)
  File "/root/anaconda3/envs/oneflow/lib/python3.5/importlib/__init__.py", line 166, in reload
    _bootstrap._exec(spec, module)
  File "<frozen importlib._bootstrap>", line 607, in _exec
AttributeError: 'NoneType' object has no attribute 'name'

During handling of the above exception, another exception occurred:

Traceback (most recent call last):
  File "/root/anaconda3/envs/oneflow/lib/python3.5/site-packages/web/application.py", line 288, in process
    return p(lambda: process(processors))
  File "/root/anaconda3/envs/oneflow/lib/python3.5/site-packages/web/application.py", line 717, in processor
    result = handler()
  File "/root/anaconda3/envs/oneflow/lib/python3.5/site-packages/web/application.py", line 288, in <lambda>
    return p(lambda: process(processors))
  File "/root/anaconda3/envs/oneflow/lib/python3.5/site-packages/web/application.py", line 297, in process
    raise self.internalerror()
  File "/root/anaconda3/envs/oneflow/lib/python3.5/site-packages/web/application.py", line 588, in internalerror
    return debugerror()
  File "/root/anaconda3/envs/oneflow/lib/python3.5/site-packages/web/debugerror.py", line 337, in debugerror
    return web._InternalError(djangoerror())
  File "/root/anaconda3/envs/oneflow/lib/python3.5/site-packages/web/debugerror.py", line 315, in djangoerror
    djangoerror_r = Template(djangoerror_t, filename=__file__, filter=websafe)
  File "/root/anaconda3/envs/oneflow/lib/python3.5/site-packages/web/template.py", line 943, in __init__
    code = self.compile_template(text, filename)
  File "/root/anaconda3/envs/oneflow/lib/python3.5/site-packages/web/template.py", line 1020, in compile_template
    compiled_code = compile(code, filename, "exec")
  File "/root/anaconda3/envs/oneflow/lib/python3.5/site-packages/web/debugerror.py", line 8
    def with (exception_type, exception_value, frames)
           ^
SyntaxError: invalid syntax

Template traceback:
    File '/root/anaconda3/envs/oneflow/lib/python3.5/site-packages/web/debugerror.py', line 8
        http://www.xfree86.org/3.3.6/COPYRIGHT2.html#5

Traceback (most recent call last):
  File "/root/anaconda3/envs/oneflow/lib/python3.5/site-packages/web/application.py", line 288, in process
    return p(lambda: process(processors))
  File "/root/anaconda3/envs/oneflow/lib/python3.5/site-packages/web/application.py", line 699, in processor
    h()
  File "/root/anaconda3/envs/oneflow/lib/python3.5/site-packages/web/application.py", line 805, in __call__
    self.check(mod)
  File "/root/anaconda3/envs/oneflow/lib/python3.5/site-packages/web/application.py", line 826, in check
    reload(mod)
  File "/root/anaconda3/envs/oneflow/lib/python3.5/importlib/__init__.py", line 166, in reload
    _bootstrap._exec(spec, module)
  File "<frozen importlib._bootstrap>", line 607, in _exec
AttributeError: 'NoneType' object has no attribute 'name'

During handling of the above exception, another exception occurred:

Traceback (most recent call last):
  File "/root/anaconda3/envs/oneflow/lib/python3.5/site-packages/web/application.py", line 288, in process
    return p(lambda: process(processors))
  File "/root/anaconda3/envs/oneflow/lib/python3.5/site-packages/web/application.py", line 717, in processor
    result = handler()
  File "/root/anaconda3/envs/oneflow/lib/python3.5/site-packages/web/application.py", line 288, in <lambda>
    return p(lambda: process(processors))
  File "/root/anaconda3/envs/oneflow/lib/python3.5/site-packages/web/application.py", line 297, in process
    raise self.internalerror()
  File "/root/anaconda3/envs/oneflow/lib/python3.5/site-packages/web/application.py", line 588, in internalerror
    return debugerror()
  File "/root/anaconda3/envs/oneflow/lib/python3.5/site-packages/web/debugerror.py", line 337, in debugerror
    return web._InternalError(djangoerror())
  File "/root/anaconda3/envs/oneflow/lib/python3.5/site-packages/web/debugerror.py", line 315, in djangoerror
    djangoerror_r = Template(djangoerror_t, filename=__file__, filter=websafe)
  File "/root/anaconda3/envs/oneflow/lib/python3.5/site-packages/web/template.py", line 943, in __init__
    code = self.compile_template(text, filename)
  File "/root/anaconda3/envs/oneflow/lib/python3.5/site-packages/web/template.py", line 1020, in compile_template
    compiled_code = compile(code, filename, "exec")
  File "/root/anaconda3/envs/oneflow/lib/python3.5/site-packages/web/debugerror.py", line 8
    def with (exception_type, exception_value, frames)
           ^
SyntaxError: invalid syntax

Template traceback:
    File '/root/anaconda3/envs/oneflow/lib/python3.5/site-packages/web/debugerror.py', line 8
        http://www.xfree86.org/3.3.6/COPYRIGHT2.html#5

During handling of the above exception, another exception occurred:

Traceback (most recent call last):
  File "/root/anaconda3/envs/oneflow/lib/python3.5/site-packages/web/application.py", line 288, in process
    return p(lambda: process(processors))
  File "/root/anaconda3/envs/oneflow/lib/python3.5/site-packages/web/application.py", line 700, in processor
    return handler()
  File "/root/anaconda3/envs/oneflow/lib/python3.5/site-packages/web/application.py", line 288, in <lambda>
    return p(lambda: process(processors))
  File "/root/anaconda3/envs/oneflow/lib/python3.5/site-packages/web/application.py", line 297, in process
    raise self.internalerror()
  File "/root/anaconda3/envs/oneflow/lib/python3.5/site-packages/web/application.py", line 588, in internalerror
    return debugerror()
  File "/root/anaconda3/envs/oneflow/lib/python3.5/site-packages/web/debugerror.py", line 337, in debugerror
    return web._InternalError(djangoerror())
  File "/root/anaconda3/envs/oneflow/lib/python3.5/site-packages/web/debugerror.py", line 315, in djangoerror
    djangoerror_r = Template(djangoerror_t, filename=__file__, filter=websafe)
  File "/root/anaconda3/envs/oneflow/lib/python3.5/site-packages/web/template.py", line 943, in __init__
    code = self.compile_template(text, filename)
  File "/root/anaconda3/envs/oneflow/lib/python3.5/site-packages/web/template.py", line 1020, in compile_template
    compiled_code = compile(code, filename, "exec")
  File "/root/anaconda3/envs/oneflow/lib/python3.5/site-packages/web/debugerror.py", line 8
    def with (exception_type, exception_value, frames)
           ^
SyntaxError: invalid syntax

Template traceback:
    File '/root/anaconda3/envs/oneflow/lib/python3.5/site-packages/web/debugerror.py', line 8
        http://www.xfree86.org/3.3.6/COPYRIGHT2.html#5

SyntaxError('invalid syntax', ('/root/anaconda3/envs/oneflow/lib/python3.5/site-packages/web/debugerror.py', 8, 12, '    def with (exception_type, exception_value, frames)\n'))
Traceback (most recent call last):
  File "/root/anaconda3/envs/oneflow/lib/python3.5/site-packages/web/application.py", line 288, in process
    return p(lambda: process(processors))
  File "/root/anaconda3/envs/oneflow/lib/python3.5/site-packages/web/application.py", line 699, in processor
    h()
  File "/root/anaconda3/envs/oneflow/lib/python3.5/site-packages/web/application.py", line 805, in __call__
    self.check(mod)
  File "/root/anaconda3/envs/oneflow/lib/python3.5/site-packages/web/application.py", line 826, in check
    reload(mod)
  File "/root/anaconda3/envs/oneflow/lib/python3.5/importlib/__init__.py", line 166, in reload
    _bootstrap._exec(spec, module)
  File "<frozen importlib._bootstrap>", line 607, in _exec
AttributeError: 'NoneType' object has no attribute 'name'

During handling of the above exception, another exception occurred:

Traceback (most recent call last):
  File "/root/anaconda3/envs/oneflow/lib/python3.5/site-packages/web/application.py", line 288, in process
    return p(lambda: process(processors))
  File "/root/anaconda3/envs/oneflow/lib/python3.5/site-packages/web/application.py", line 717, in processor
    result = handler()
  File "/root/anaconda3/envs/oneflow/lib/python3.5/site-packages/web/application.py", line 288, in <lambda>
    return p(lambda: process(processors))
  File "/root/anaconda3/envs/oneflow/lib/python3.5/site-packages/web/application.py", line 297, in process
    raise self.internalerror()
  File "/root/anaconda3/envs/oneflow/lib/python3.5/site-packages/web/application.py", line 588, in internalerror
    return debugerror()
  File "/root/anaconda3/envs/oneflow/lib/python3.5/site-packages/web/debugerror.py", line 337, in debugerror
    return web._InternalError(djangoerror())
  File "/root/anaconda3/envs/oneflow/lib/python3.5/site-packages/web/debugerror.py", line 315, in djangoerror
    djangoerror_r = Template(djangoerror_t, filename=__file__, filter=websafe)
  File "/root/anaconda3/envs/oneflow/lib/python3.5/site-packages/web/template.py", line 943, in __init__
    code = self.compile_template(text, filename)
  File "/root/anaconda3/envs/oneflow/lib/python3.5/site-packages/web/template.py", line 1020, in compile_template
    compiled_code = compile(code, filename, "exec")
  File "/root/anaconda3/envs/oneflow/lib/python3.5/site-packages/web/debugerror.py", line 8
    def with (exception_type, exception_value, frames)
           ^
SyntaxError: invalid syntax

Template traceback:
    File '/root/anaconda3/envs/oneflow/lib/python3.5/site-packages/web/debugerror.py', line 8
        http://www.xfree86.org/3.3.6/COPYRIGHT2.html#5

During handling of the above exception, another exception occurred:

Traceback (most recent call last):
  File "/root/anaconda3/envs/oneflow/lib/python3.5/site-packages/web/application.py", line 288, in process
    return p(lambda: process(processors))
  File "/root/anaconda3/envs/oneflow/lib/python3.5/site-packages/web/application.py", line 700, in processor
    return handler()
  File "/root/anaconda3/envs/oneflow/lib/python3.5/site-packages/web/application.py", line 288, in <lambda>
    return p(lambda: process(processors))
  File "/root/anaconda3/envs/oneflow/lib/python3.5/site-packages/web/application.py", line 297, in process
    raise self.internalerror()
  File "/root/anaconda3/envs/oneflow/lib/python3.5/site-packages/web/application.py", line 588, in internalerror
    return debugerror()
  File "/root/anaconda3/envs/oneflow/lib/python3.5/site-packages/web/debugerror.py", line 337, in debugerror
    return web._InternalError(djangoerror())
  File "/root/anaconda3/envs/oneflow/lib/python3.5/site-packages/web/debugerror.py", line 315, in djangoerror
    djangoerror_r = Template(djangoerror_t, filename=__file__, filter=websafe)
  File "/root/anaconda3/envs/oneflow/lib/python3.5/site-packages/web/template.py", line 943, in __init__
    code = self.compile_template(text, filename)
  File "/root/anaconda3/envs/oneflow/lib/python3.5/site-packages/web/template.py", line 1020, in compile_template
    compiled_code = compile(code, filename, "exec")
  File "/root/anaconda3/envs/oneflow/lib/python3.5/site-packages/web/debugerror.py", line 8
    def with (exception_type, exception_value, frames)
           ^
SyntaxError: invalid syntax

Template traceback:
    File '/root/anaconda3/envs/oneflow/lib/python3.5/site-packages/web/debugerror.py', line 8
        http://www.xfree86.org/3.3.6/COPYRIGHT2.html#5

During handling of the above exception, another exception occurred:

Traceback (most recent call last):
  File "/root/anaconda3/envs/oneflow/lib/python3.5/site-packages/cheroot/server.py", line 1269, in communicate
    req.respond()
  File "/root/anaconda3/envs/oneflow/lib/python3.5/site-packages/cheroot/server.py", line 1071, in respond
    self.server.gateway(self).respond()
  File "/root/anaconda3/envs/oneflow/lib/python3.5/site-packages/cheroot/wsgi.py", line 143, in respond
    response = self.req.server.wsgi_app(self.env, self.start_response)
  File "/root/anaconda3/envs/oneflow/lib/python3.5/site-packages/web/httpserver.py", line 306, in __call__
    return self.app(environ, xstart_response)
  File "/root/anaconda3/envs/oneflow/lib/python3.5/site-packages/web/httpserver.py", line 273, in __call__
    return self.app(environ, start_response)
  File "/root/anaconda3/envs/oneflow/lib/python3.5/site-packages/web/application.py", line 329, in wsgi
    result = self.handle_with_processors()
  File "/root/anaconda3/envs/oneflow/lib/python3.5/site-packages/web/application.py", line 300, in handle_with_processors
    return process(self.processors)
  File "/root/anaconda3/envs/oneflow/lib/python3.5/site-packages/web/application.py", line 297, in process
    raise self.internalerror()
  File "/root/anaconda3/envs/oneflow/lib/python3.5/site-packages/web/application.py", line 588, in internalerror
    return debugerror()
  File "/root/anaconda3/envs/oneflow/lib/python3.5/site-packages/web/debugerror.py", line 337, in debugerror
    return web._InternalError(djangoerror())
  File "/root/anaconda3/envs/oneflow/lib/python3.5/site-packages/web/debugerror.py", line 315, in djangoerror
    djangoerror_r = Template(djangoerror_t, filename=__file__, filter=websafe)
  File "/root/anaconda3/envs/oneflow/lib/python3.5/site-packages/web/template.py", line 943, in __init__
    code = self.compile_template(text, filename)
  File "/root/anaconda3/envs/oneflow/lib/python3.5/site-packages/web/template.py", line 1020, in compile_template
    compiled_code = compile(code, filename, "exec")
  File "/root/anaconda3/envs/oneflow/lib/python3.5/site-packages/web/debugerror.py", line 8
    def with (exception_type, exception_value, frames)
           ^
SyntaxError: invalid syntax

Template traceback:
    File '/root/anaconda3/envs/oneflow/lib/python3.5/site-packages/web/debugerror.py', line 8
        http://www.xfree86.org/3.3.6/COPYRIGHT2.html#5
Traceback (most recent call last):
  File "/root/anaconda3/envs/oneflow/lib/python3.5/site-packages/web/application.py", line 288, in process
    return p(lambda: process(processors))
  File "/root/anaconda3/envs/oneflow/lib/python3.5/site-packages/web/application.py", line 699, in processor
    h()
  File "/root/anaconda3/envs/oneflow/lib/python3.5/site-packages/web/application.py", line 805, in __call__
    self.check(mod)
  File "/root/anaconda3/envs/oneflow/lib/python3.5/site-packages/web/application.py", line 826, in check
    reload(mod)
  File "/root/anaconda3/envs/oneflow/lib/python3.5/importlib/__init__.py", line 166, in reload
    _bootstrap._exec(spec, module)
  File "<frozen importlib._bootstrap>", line 607, in _exec
AttributeError: 'NoneType' object has no attribute 'name'

Traceback (most recent call last):
  File "/root/anaconda3/envs/oneflow/lib/python3.5/site-packages/web/application.py", line 288, in process
    return p(lambda: process(processors))
  File "/root/anaconda3/envs/oneflow/lib/python3.5/site-packages/web/application.py", line 699, in processor
    h()
  File "/root/anaconda3/envs/oneflow/lib/python3.5/site-packages/web/application.py", line 805, in __call__
    self.check(mod)
  File "/root/anaconda3/envs/oneflow/lib/python3.5/site-packages/web/application.py", line 826, in check
    reload(mod)
  File "/root/anaconda3/envs/oneflow/lib/python3.5/importlib/__init__.py", line 166, in reload
    _bootstrap._exec(spec, module)
  File "<frozen importlib._bootstrap>", line 607, in _exec
AttributeError: 'NoneType' object has no attribute 'name'

During handling of the above exception, another exception occurred:

Traceback (most recent call last):
  File "/root/anaconda3/envs/oneflow/lib/python3.5/site-packages/web/application.py", line 288, in process
    return p(lambda: process(processors))
  File "/root/anaconda3/envs/oneflow/lib/python3.5/site-packages/web/application.py", line 717, in processor
    result = handler()
  File "/root/anaconda3/envs/oneflow/lib/python3.5/site-packages/web/application.py", line 288, in <lambda>
    return p(lambda: process(processors))
  File "/root/anaconda3/envs/oneflow/lib/python3.5/site-packages/web/application.py", line 297, in process
    raise self.internalerror()
  File "/root/anaconda3/envs/oneflow/lib/python3.5/site-packages/web/application.py", line 588, in internalerror
    return debugerror()
  File "/root/anaconda3/envs/oneflow/lib/python3.5/site-packages/web/debugerror.py", line 337, in debugerror
    return web._InternalError(djangoerror())
  File "/root/anaconda3/envs/oneflow/lib/python3.5/site-packages/web/debugerror.py", line 315, in djangoerror
    djangoerror_r = Template(djangoerror_t, filename=__file__, filter=websafe)
  File "/root/anaconda3/envs/oneflow/lib/python3.5/site-packages/web/template.py", line 943, in __init__
    code = self.compile_template(text, filename)
  File "/root/anaconda3/envs/oneflow/lib/python3.5/site-packages/web/template.py", line 1020, in compile_template
    compiled_code = compile(code, filename, "exec")
  File "/root/anaconda3/envs/oneflow/lib/python3.5/site-packages/web/debugerror.py", line 8
    def with (exception_type, exception_value, frames)
           ^
SyntaxError: invalid syntax

Template traceback:
    File '/root/anaconda3/envs/oneflow/lib/python3.5/site-packages/web/debugerror.py', line 8
        http://www.xfree86.org/3.3.6/COPYRIGHT2.html#5

Traceback (most recent call last):
  File "/root/anaconda3/envs/oneflow/lib/python3.5/site-packages/web/application.py", line 288, in process
    return p(lambda: process(processors))
  File "/root/anaconda3/envs/oneflow/lib/python3.5/site-packages/web/application.py", line 699, in processor
    h()
  File "/root/anaconda3/envs/oneflow/lib/python3.5/site-packages/web/application.py", line 805, in __call__
    self.check(mod)
  File "/root/anaconda3/envs/oneflow/lib/python3.5/site-packages/web/application.py", line 826, in check
    reload(mod)
  File "/root/anaconda3/envs/oneflow/lib/python3.5/importlib/__init__.py", line 166, in reload
    _bootstrap._exec(spec, module)
  File "<frozen importlib._bootstrap>", line 607, in _exec
AttributeError: 'NoneType' object has no attribute 'name'

During handling of the above exception, another exception occurred:

Traceback (most recent call last):
  File "/root/anaconda3/envs/oneflow/lib/python3.5/site-packages/web/application.py", line 288, in process
    return p(lambda: process(processors))
  File "/root/anaconda3/envs/oneflow/lib/python3.5/site-packages/web/application.py", line 717, in processor
    result = handler()
  File "/root/anaconda3/envs/oneflow/lib/python3.5/site-packages/web/application.py", line 288, in <lambda>
    return p(lambda: process(processors))
  File "/root/anaconda3/envs/oneflow/lib/python3.5/site-packages/web/application.py", line 297, in process
    raise self.internalerror()
  File "/root/anaconda3/envs/oneflow/lib/python3.5/site-packages/web/application.py", line 588, in internalerror
    return debugerror()
  File "/root/anaconda3/envs/oneflow/lib/python3.5/site-packages/web/debugerror.py", line 337, in debugerror
    return web._InternalError(djangoerror())
  File "/root/anaconda3/envs/oneflow/lib/python3.5/site-packages/web/debugerror.py", line 315, in djangoerror
    djangoerror_r = Template(djangoerror_t, filename=__file__, filter=websafe)
  File "/root/anaconda3/envs/oneflow/lib/python3.5/site-packages/web/template.py", line 943, in __init__
    code = self.compile_template(text, filename)
  File "/root/anaconda3/envs/oneflow/lib/python3.5/site-packages/web/template.py", line 1020, in compile_template
    compiled_code = compile(code, filename, "exec")
  File "/root/anaconda3/envs/oneflow/lib/python3.5/site-packages/web/debugerror.py", line 8
    def with (exception_type, exception_value, frames)
           ^
SyntaxError: invalid syntax

Template traceback:
    File '/root/anaconda3/envs/oneflow/lib/python3.5/site-packages/web/debugerror.py', line 8
        http://www.xfree86.org/3.3.6/COPYRIGHT2.html#5

During handling of the above exception, another exception occurred:

Traceback (most recent call last):
  File "/root/anaconda3/envs/oneflow/lib/python3.5/site-packages/web/application.py", line 288, in process
    return p(lambda: process(processors))
  File "/root/anaconda3/envs/oneflow/lib/python3.5/site-packages/web/application.py", line 700, in processor
    return handler()
  File "/root/anaconda3/envs/oneflow/lib/python3.5/site-packages/web/application.py", line 288, in <lambda>
    return p(lambda: process(processors))
  File "/root/anaconda3/envs/oneflow/lib/python3.5/site-packages/web/application.py", line 297, in process
    raise self.internalerror()
  File "/root/anaconda3/envs/oneflow/lib/python3.5/site-packages/web/application.py", line 588, in internalerror
    return debugerror()
  File "/root/anaconda3/envs/oneflow/lib/python3.5/site-packages/web/debugerror.py", line 337, in debugerror
    return web._InternalError(djangoerror())
  File "/root/anaconda3/envs/oneflow/lib/python3.5/site-packages/web/debugerror.py", line 315, in djangoerror
    djangoerror_r = Template(djangoerror_t, filename=__file__, filter=websafe)
  File "/root/anaconda3/envs/oneflow/lib/python3.5/site-packages/web/template.py", line 943, in __init__
    code = self.compile_template(text, filename)
  File "/root/anaconda3/envs/oneflow/lib/python3.5/site-packages/web/template.py", line 1020, in compile_template
    compiled_code = compile(code, filename, "exec")
  File "/root/anaconda3/envs/oneflow/lib/python3.5/site-packages/web/debugerror.py", line 8
    def with (exception_type, exception_value, frames)
           ^
SyntaxError: invalid syntax

Template traceback:
    File '/root/anaconda3/envs/oneflow/lib/python3.5/site-packages/web/debugerror.py', line 8
        http://www.xfree86.org/3.3.6/COPYRIGHT2.html#5

SyntaxError('invalid syntax', ('/root/anaconda3/envs/oneflow/lib/python3.5/site-packages/web/debugerror.py', 8, 12, '    def with (exception_type, exception_value, frames)\n'))
Traceback (most recent call last):
  File "/root/anaconda3/envs/oneflow/lib/python3.5/site-packages/web/application.py", line 288, in process
    return p(lambda: process(processors))
  File "/root/anaconda3/envs/oneflow/lib/python3.5/site-packages/web/application.py", line 699, in processor
    h()
  File "/root/anaconda3/envs/oneflow/lib/python3.5/site-packages/web/application.py", line 805, in __call__
    self.check(mod)
  File "/root/anaconda3/envs/oneflow/lib/python3.5/site-packages/web/application.py", line 826, in check
    reload(mod)
  File "/root/anaconda3/envs/oneflow/lib/python3.5/importlib/__init__.py", line 166, in reload
    _bootstrap._exec(spec, module)
  File "<frozen importlib._bootstrap>", line 607, in _exec
AttributeError: 'NoneType' object has no attribute 'name'

During handling of the above exception, another exception occurred:

Traceback (most recent call last):
  File "/root/anaconda3/envs/oneflow/lib/python3.5/site-packages/web/application.py", line 288, in process
    return p(lambda: process(processors))
  File "/root/anaconda3/envs/oneflow/lib/python3.5/site-packages/web/application.py", line 717, in processor
    result = handler()
  File "/root/anaconda3/envs/oneflow/lib/python3.5/site-packages/web/application.py", line 288, in <lambda>
    return p(lambda: process(processors))
  File "/root/anaconda3/envs/oneflow/lib/python3.5/site-packages/web/application.py", line 297, in process
    raise self.internalerror()
  File "/root/anaconda3/envs/oneflow/lib/python3.5/site-packages/web/application.py", line 588, in internalerror
    return debugerror()
  File "/root/anaconda3/envs/oneflow/lib/python3.5/site-packages/web/debugerror.py", line 337, in debugerror
    return web._InternalError(djangoerror())
  File "/root/anaconda3/envs/oneflow/lib/python3.5/site-packages/web/debugerror.py", line 315, in djangoerror
    djangoerror_r = Template(djangoerror_t, filename=__file__, filter=websafe)
  File "/root/anaconda3/envs/oneflow/lib/python3.5/site-packages/web/template.py", line 943, in __init__
    code = self.compile_template(text, filename)
  File "/root/anaconda3/envs/oneflow/lib/python3.5/site-packages/web/template.py", line 1020, in compile_template
    compiled_code = compile(code, filename, "exec")
  File "/root/anaconda3/envs/oneflow/lib/python3.5/site-packages/web/debugerror.py", line 8
    def with (exception_type, exception_value, frames)
           ^
SyntaxError: invalid syntax

Template traceback:
    File '/root/anaconda3/envs/oneflow/lib/python3.5/site-packages/web/debugerror.py', line 8
        http://www.xfree86.org/3.3.6/COPYRIGHT2.html#5

During handling of the above exception, another exception occurred:

Traceback (most recent call last):
  File "/root/anaconda3/envs/oneflow/lib/python3.5/site-packages/web/application.py", line 288, in process
    return p(lambda: process(processors))
  File "/root/anaconda3/envs/oneflow/lib/python3.5/site-packages/web/application.py", line 700, in processor
    return handler()
  File "/root/anaconda3/envs/oneflow/lib/python3.5/site-packages/web/application.py", line 288, in <lambda>
    return p(lambda: process(processors))
  File "/root/anaconda3/envs/oneflow/lib/python3.5/site-packages/web/application.py", line 297, in process
    raise self.internalerror()
  File "/root/anaconda3/envs/oneflow/lib/python3.5/site-packages/web/application.py", line 588, in internalerror
    return debugerror()
  File "/root/anaconda3/envs/oneflow/lib/python3.5/site-packages/web/debugerror.py", line 337, in debugerror
    return web._InternalError(djangoerror())
  File "/root/anaconda3/envs/oneflow/lib/python3.5/site-packages/web/debugerror.py", line 315, in djangoerror
    djangoerror_r = Template(djangoerror_t, filename=__file__, filter=websafe)
  File "/root/anaconda3/envs/oneflow/lib/python3.5/site-packages/web/template.py", line 943, in __init__
    code = self.compile_template(text, filename)
  File "/root/anaconda3/envs/oneflow/lib/python3.5/site-packages/web/template.py", line 1020, in compile_template
    compiled_code = compile(code, filename, "exec")
  File "/root/anaconda3/envs/oneflow/lib/python3.5/site-packages/web/debugerror.py", line 8
    def with (exception_type, exception_value, frames)
           ^
SyntaxError: invalid syntax

Template traceback:
    File '/root/anaconda3/envs/oneflow/lib/python3.5/site-packages/web/debugerror.py', line 8
        http://www.xfree86.org/3.3.6/COPYRIGHT2.html#5

During handling of the above exception, another exception occurred:

Traceback (most recent call last):
  File "/root/anaconda3/envs/oneflow/lib/python3.5/site-packages/cheroot/server.py", line 1269, in communicate
    req.respond()
  File "/root/anaconda3/envs/oneflow/lib/python3.5/site-packages/cheroot/server.py", line 1071, in respond
    self.server.gateway(self).respond()
  File "/root/anaconda3/envs/oneflow/lib/python3.5/site-packages/cheroot/wsgi.py", line 143, in respond
    response = self.req.server.wsgi_app(self.env, self.start_response)
  File "/root/anaconda3/envs/oneflow/lib/python3.5/site-packages/web/httpserver.py", line 306, in __call__
    return self.app(environ, xstart_response)
  File "/root/anaconda3/envs/oneflow/lib/python3.5/site-packages/web/httpserver.py", line 273, in __call__
    return self.app(environ, start_response)
  File "/root/anaconda3/envs/oneflow/lib/python3.5/site-packages/web/application.py", line 329, in wsgi
    result = self.handle_with_processors()
  File "/root/anaconda3/envs/oneflow/lib/python3.5/site-packages/web/application.py", line 300, in handle_with_processors
    return process(self.processors)
  File "/root/anaconda3/envs/oneflow/lib/python3.5/site-packages/web/application.py", line 297, in process
    raise self.internalerror()
  File "/root/anaconda3/envs/oneflow/lib/python3.5/site-packages/web/application.py", line 588, in internalerror
    return debugerror()
  File "/root/anaconda3/envs/oneflow/lib/python3.5/site-packages/web/debugerror.py", line 337, in debugerror
    return web._InternalError(djangoerror())
  File "/root/anaconda3/envs/oneflow/lib/python3.5/site-packages/web/debugerror.py", line 315, in djangoerror
    djangoerror_r = Template(djangoerror_t, filename=__file__, filter=websafe)
  File "/root/anaconda3/envs/oneflow/lib/python3.5/site-packages/web/template.py", line 943, in __init__
    code = self.compile_template(text, filename)
  File "/root/anaconda3/envs/oneflow/lib/python3.5/site-packages/web/template.py", line 1020, in compile_template
    compiled_code = compile(code, filename, "exec")
  File "/root/anaconda3/envs/oneflow/lib/python3.5/site-packages/web/debugerror.py", line 8
    def with (exception_type, exception_value, frames)
           ^
SyntaxError: invalid syntax

Template traceback:
    File '/root/anaconda3/envs/oneflow/lib/python3.5/site-packages/web/debugerror.py', line 8
        http://www.xfree86.org/3.3.6/COPYRIGHT2.html#5
